Workbook

Sheet GoldStandard_Scores
A1: SCOTC v3.0 — Gold Standard Expert Consensus Scores | 180 Requirements × 9 Domains
A2: Set by expert group consensus (all 3 annotators + supervisor). Gold_Total = denominator in Coverage Ratio formula. Complexity levels: Simple = straightforward single-step flow | Medium = conditional logic | Complex = multi-step/cross-system.
A4: REQ_ID | B4: Domain | C4: Requirement | D4: Complexity | E4: Gold_C (1-5) | F4: Gold_R (1-5) | G4: Gold_TR (1-5) | H4: Gold_Total
A5: REQ-001 | B5: Authentication | C5: User Registration | D5: Medium | E5: 4 | F5: 4 | G5: 4 | H5: =SUM(E5:G5) -> 12
A6: REQ-002 | B6: Authentication | C6: User Login | D6: Simple | E6: 4 | F6: 4 | G6: 4 | H6: =SUM(E6:G6) -> 12
A7: REQ-003 | B7: Authentication | C7: Password Reset via Email | D7: Medium | E7: 4 | F7: 4 | G7: 4 | H7: =SUM(E7:G7) -> 12
A8: REQ-004 | B8: Authentication | C8: Password Reset via OTP | D8: Medium | E8: 4 | F8: 4 | G8: 4 | H8: =SUM(E8:G8) -> 12
A9: REQ-005 | B9: Authentication | C9: Multi-Factor Authentication (MFA) | D9: Complex | E9: 4 | F9: 4 | G9: 4 | H9: =SUM(E9:G9) -> 12
A10: REQ-006 | B10: Authentication | C10: Session Timeout | D10: Simple | E10: 4 | F10: 4 | G10: 4 | H10: =SUM(E10:G10) -> 12
A11: REQ-007 | B11: Authentication | C11: Account Lockout After Failed Attempts | D11: Medium | E11: 4 | F11: 4 | G11: 4 | H11: =SUM(E11:G11) -> 12
A12: REQ-008 | B12: Authentication | C12: Change Password | D12: Simple | E12: 4 | F12: 4 | G12: 4 | H12: =SUM(E12:G12) -> 12
A13: REQ-009 | B13: Authentication | C13: Remember Me Functionality | D13: Medium | E13: 4 | F13: 4 | G13: 4 | H13: =SUM(E13:G13) -> 12
A14: REQ-010 | B14: Authentication | C14: Logout from All Devices | D14: Medium | E14: 4 | F14: 4 | G14: 4 | H14: =SUM(E14:G14) -> 12
A15: REQ-011 | B15: Authentication | C15: CAPTCHA Verification | D15: Medium | E15: 4 | F15: 4 | G15: 4 | H15: =SUM(E15:G15) -> 12
A16: REQ-012 | B16: Authentication | C16: Email Verification After Registration | D16: Medium | E16: 4 | F16: 4 | G16: 4 | H16: =SUM(E16:G16) -> 12
... A184: REQ-180 | B184: e-Governance | C184: Document Apostille Request | D184: Complex | E184: 4 | F184: 4 | G184: 4 | H184: =SUM(E184:G184) -> 12

Sheet Annotator1_Scores
A1: SCOTC v3.0 — Annotator 1 Scores | 180 Requirements × 11 Models
A2: REQ ID | B2: Domain | C2: Requirement | D2: Complexity | E2: ChatGPT | I2: Gemini | M2: GPT-4o | Q2: Claude | U2: Llama 3.3 70B | Y2: Mistral Large 2 | AC2: DeepSeek-V3 | AG2: Grok-2 | AK2: Qwen2.5 72B | AO2: Command R+ | AS2: Gemma 2 27B
E3: C (1-5) | F3: R (1-5) | G3: TR (1-5) | H3: Total | I3: C (1-5) | J3: R (1-5) | K3: TR (1-5) | L3: Total | M3: C (1-5) | N3: R (1-5) | O3: TR (1-5) | P3: Total | Q3: C (1-5) | R3: R (1-5) | S3: TR (1-5) | T3: Total | U3: C (1-5) | V3: R (1-5) | W3: TR (1-5) | X3: Total | Y3: C (1-5) | Z3: R (1-5) | AA3: TR (1-5) | AB3: Total | AC3: C (1-5) | AD3: R (1-5) | AE3: TR (1-5) | AF3: Total | AG3: C (1-5) | AH3: R (1-5) | AI3: TR (1-5) | AJ3: Total | AK3: C (1-5) | AL3: R (1-5) | AM3: TR (1-5) | AN3: Total | AO3: C (1-5) | AP3: R (1-5) | AQ3: TR (1-5) | AR3: Total | AS3: C (1-5) | AT3: R (1-5) | AU3: TR (1-5) | AV3: Total
A4: REQ-001 | B4: Authentication | C4: User Registration | D4: Medium | E4: 4 | F4: 3 | G4: 3 | H4: =SUM(E4:G4) -> 10 | I4: 3 | J4: 4 | K4: 3 | L4: =SUM(I4:K4) -> 10 | M4: 4 | N4: 3 | O4: 3 | P4: =SUM(M4:O4) -> 10 | Q4: 3 | R4: 3 | S4: 3 | T4: =SUM(Q4:S4) -> 9 | U4: 3 | V4: 3 | W4: 3 | X4: =SUM(U4:W4) -> 9 | Y4: 3 | Z4: 3 | AA4: 3 | AB4: =SUM(Y4:AA4) -> 9 | AC4: 3 | AD4: 4 | AE4: 3 | AF4: =SUM(AC4:AE4) -> 10 | AG4: 4 | AH4: 3 | AI4: 3 | AJ4: =SUM(AG4:AI4) -> 10 | AK4: 4 | AL4: 3 | AM4: 3 | AN4: =SUM(AK4:AM4) -> 10 | AO4: 3 | AP4: 3 | AQ4: 3 | AR4: =SUM(AO4:AQ4) -> 9 | AS4: 3 | AT4: 3 | AU4: 3 | AV4: =SUM(AS4:AU4) -> 9
A5: REQ-002 | B5: Authentication | C5: User Login | D5: Simple | E5: 3 | F5: 3 | G5: 3 | H5: =SUM(E5:G5) -> 9 | I5: 3 | J5: 3 | K5: 3 | L5: =SUM(I5:K5) -> 9 | M5: 4 | N5: 3 | O5: 4 | P5: =SUM(M5:O5) -> 11 | Q5: 4 | R5: 3 | S5: 3 | T5: =SUM(Q5:S5) -> 10 | U5: 4 | V5: 4 | W5: 4 | X5: =SUM(U5:W5) -> 12 | Y5: 3 | Z5: 4 | AA5: 3 | AB5: =SUM(Y5:AA5) -> 10 | AC5: 3 | AD5: 4 | AE5: 4 | AF5: =SUM(AC5:AE5) -> 11 | AG5: 3 | AH5: 3 | AI5: 3 | AJ5: =SUM(AG5:AI5) -> 9 | AK5: 3 | AL5: 4 | AM5: 4 | AN5: =SUM(AK5:AM5) -> 11 | AO5: 4 | AP5: 4 | AQ5: 3 | AR5: =SUM(AO5:AQ5) -> 11 | AS5: 3 | AT5: 3 | AU5: 3 | AV5: =SUM(AS5:AU5) -> 9
A6: REQ-003 | B6: Authentication | C6: Password Reset via Email | D6: Medium | E6: 4 | F6: 3 | G6: 3 | H6: =SUM(E6:G6) -> 10 | I6: 3 | J6: 4 | K6: 3 | L6: =SUM(I6:K6) -> 10 | M6: 4 | N6: 4 | O6: 4 | P6: =SUM(M6:O6) -> 12 | Q6: 4 | R6: 3 | S6: 4 | T6: =SUM(Q6:S6) -> 11 | U6: 3 | V6: 3 | W6: 3 | X6: =SUM(U6:W6) -> 9 | Y6: 3 | Z6: 3 | AA6: 3 | AB6: =SUM(Y6:AA6) -> 9 | AC6: 3 | AD6: 3 | AE6: 3 | AF6: =SUM(AC6:AE6) -> 9 | AG6: 4 | AH6: 4 | AI6: 3 | AJ6: =SUM(AG6:AI6) -> 11 | AK6: 3 | AL6: 4 | AM6: 4 | AN6: =SUM(AK6:AM6) -> 11 | AO6: 3 | AP6: 3 | AQ6: 3 | AR6: =SUM(AO6:AQ6) -> 9 | AS6: 4 | AT6: 4 | AU6: 3 | AV6: =SUM(AS6:AU6) -> 11
A7: REQ-004 | B7: Authentication | C7: Password Reset via OTP | D7: Medium | E7: 3 | F7: 4 | G7: 3 | H7: =SUM(E7:G7) -> 10 | I7: 4 | J7: 3 | K7: 3 | L7: =SUM(I7:K7) -> 10 | M7: 4 | N7: 3 | O7: 4 | P7: =SUM(M7:O7) -> 11 | Q7: 3 | R7: 4 | S7: 3 | T7: =SUM(Q7:S7) -> 10 | U7: 3 | V7: 3 | W7: 3 | X7: =SUM(U7:W7) -> 9 | Y7: 3 | Z7: 3 | AA7: 3 | AB7: =SUM(Y7:AA7) -> 9 | AC7: 3 | AD7: 4 | AE7: 4 | AF7: =SUM(AC7:AE7) -> 11 | AG7: 4 | AH7: 4 | AI7: 3 | AJ7: =SUM(AG7:AI7) -> 11 | AK7: 3 | AL7: 3 | AM7: 3 | AN7: =SUM(AK7:AM7) -> 9 | AO7: 3 | AP7: 3 | AQ7: 3 | AR7: =SUM(AO7:AQ7) -> 9 | AS7: 3 | AT7: 3 | AU7: 3 | AV7: =SUM(AS7:AU7) -> 9
A8: REQ-005 | B8: Authentication | C8: Multi-Factor Authentication (MFA) | D8: Complex | E8: 3 | F8: 3 | G8: 3 | H8: =SUM(E8:G8) -> 9 | I8: 3 | J8: 3 | K8: 4 | L8: =SUM(I8:K8) -> 10 | M8: 4 | N8: 4 | O8: 4 | P8: =SUM(M8:O8) -> 12 | Q8: 3 | R8: 4 | S8: 3 | T8: =SUM(Q8:S8) -> 10 | U8: 3 | V8: 3 | W8: 3 | X8: =SUM(U8:W8) -> 9 | Y8: 3 | Z8: 3 | AA8: 3 | AB8: =SUM(Y8:AA8) -> 9 | AC8: 3 | AD8: 3 | AE8: 3 | AF8: =SUM(AC8:AE8) -> 9 | AG8: 3 | AH8: 3 | AI8: 3 | AJ8: =SUM(AG8:AI8) -> 9 | AK8: 3 | AL8: 3 | AM8: 3 | AN8: =SUM(AK8:AM8) -> 9 | AO8: 3 | AP8: 2 | AQ8: 3 | AR8: =SUM(AO8:AQ8) -> 8 | AS8: 3 | AT8: 3 | AU8: 3 | AV8: =SUM(AS8:AU8) -> 9
A9: REQ-006 | B9: Authentication | C9: Session Timeout | D9: Simple | E9: 4 | F9: 3 | G9: 3 | H9: =SUM(E9:G9) -> 10 | I9: 3 | J9: 3 | K9: 3 | L9: =SUM(I9:K9) -> 9 | M9: 3 | N9: 3 | O9: 3 | P9: =SUM(M9:O9) -> 9 | Q9: 3 | R9: 3 | S9: 3 | T9: =SUM(Q9:S9) -> 9 | U9: 3 | V9: 4 | W9: 3 | X9: =SUM(U9:W9) -> 10 | Y9: 3 | Z9: 3 | AA9: 4 | AB9: =SUM(Y9:AA9) -> 10 | AC9: 4 | AD9: 3 | AE9: 3 | AF9: =SUM(AC9:AE9) -> 10 | AG9: 4 | AH9: 4 | AI9: 4 | AJ9: =SUM(AG9:AI9) -> 12 | AK9: 3 | AL9: 3 | AM9: 4 | AN9: =SUM(AK9:AM9) -> 10 | AO9: 3 | AP9: 3 | AQ9: 3 | AR9: =SUM(AO9:AQ9) -> 9 | AS9: 4 | AT9: 3 | AU9: 3 | AV9: =SUM(AS9:AU9) -> 10
A10: REQ-007 | B10: Authentication | C10: Account Lockout After Failed Attempts | D10: Medium | E10: 3 | F10: 4 | G10: 3 | H10: =SUM(E10:G10) -> 10 | I10: 3 | J10: 3 | K10: 3 | L10: =SUM(I10:K10) -> 9 | M10: 4 | N10: 3 | O10: 3 | P10: =SUM(M10:O10) -> 10 | Q10: 3 | R10: 4 | S10: 3 | T10: =SUM(Q10:S10) -> 10 | U10: 4 | V10: 4 | W10: 3 | X10: =SUM(U10:W10) -> 11 | Y10: 3 | Z10: 3 | AA10: 3 | AB10: =SUM(Y10:AA10) -> 9 | AC10: 3 | AD10: 3 | AE10: 4 | AF10: =SUM(AC10:AE10) -> 10 | AG10: 3 | AH10: 3 | AI10: 3 | AJ10: =SUM(AG10:AI10) -> 9 | AK10: 3 | AL10: 3 | AM10: 3 | AN10: =SUM(AK10:AM10) -> 9 | AO10: 4 | AP10: 3 | AQ10: 3 | AR10: =SUM(AO10:AQ10) -> 10 | AS10: 4 | AT10: 3 | AU10: 3 | AV10: =SUM(AS10:AU10) -> 10
A11: REQ-008 | B11: Authentication | C11: Change Password | D11: Simple | E11: 4 | F11: 4 | G11: 3 | H11: =SUM(E11:G11) -> 11 | I11: 3 | J11: 4 | K11: 3 | L11: =SUM(I11:K11) -> 10 | M11: 4 | N11: 3 | O11: 4 | P11: =SUM(M11:O11) -> 11 | Q11: 3 | R11: 3 | S11: 3 | T11: =SUM(Q11:S11) -> 9 | U11: 3 | V11: 3 | W11: 3 | X11: =SUM(U11:W11) -> 9 | Y11: 3 | Z11: 3 | AA11: 3 | AB11: =SUM(Y11:AA11) -> 9 | AC11: 4 | AD11: 4 | AE11: 3 | AF11: =SUM(AC11:AE11) -> 11 | AG11: 4 | AH11: 4 | AI11: 4 | AJ11: =SUM(AG11:AI11) -> 12 | AK11: 4 | AL11: 4 | AM11: 3 | AN11: =SUM(AK11:AM11) -> 11 | AO11: 3 | AP11: 4 | AQ11: 3 | AR11: =SUM(AO11:AQ11) -> 10 | AS11: 3 | AT11: 3 | AU11: 3 | AV11: =SUM(AS11:AU11) -> 9
A12: REQ-009 | B12: Authentication | C12: Remember Me Functionality | D12: Medium | E12: 3 | F12: 3 | G12: 3 | H12: =SUM(E12:G12) -> 9 | I12: 4 | J12: 4 | K12: 3 | L12: =SUM(I12:K12) -> 11 | M12: 4 | N12: 4 | O12: 4 | P12: =SUM(M12:O12) -> 12 | Q12: 4 | R12: 4 | S12: 4 | T12: =SUM(Q12:S12) -> 12 | U12: 3 | V12: 4 | W12: 3 | X12: =SUM(U12:W12) -> 10 | Y12: 3 | Z12: 4 | AA12: 3 | AB12: =SUM(Y12:AA12) -> 10 | AC12: 3 | AD12: 3 | AE12: 3 | AF12: =SUM(AC12:AE12) -> 9 | AG12: 3 | AH12: 3 | AI12: 3 | AJ12: =SUM(AG12:AI12) -> 9 | AK12: 4 | AL12: 3 | AM12: 3 | AN12: =SUM(AK12:AM12) -> 10 | AO12: 3 | AP12: 3 | AQ12: 3 | AR12: =SUM(AO12:AQ12) -> 9 | AS12: 3 | AT12: 3 | AU12: 4 | AV12: =SUM(AS12:AU12) -> 10
A13: REQ-010 | B13: Authentication | C13: Logout from All Devices | D13: Medium | E13: 3 | F13: 3 | G13: 4 | H13: =SUM(E13:G13) -> 10 | I13: 4 | J13: 3 | K13: 3 | L13: =SUM(I13:K13) -> 10 | M13: 4 | N13: 3 | O13: 4 | P13: =SUM(M13:O13) -> 11 | Q13: 3 | R13: 3 | S13: 3 | T13: =SUM(Q13:S13) -> 9 | U13: 4 | V13: 3 | W13: 4 | X13: =SUM(U13:W13) -> 11 | Y13: 4 | Z13: 4 | AA13: 4 | AB13: =SUM(Y13:AA13) -> 12 | AC13: 3 | AD13: 3 | AE13: 3 | AF13: =SUM(AC13:AE13) -> 9 | AG13: 3 | AH13: 4 | AI13: 3 | AJ13: =SUM(AG13:AI13) -> 10 | AK13: 3 | AL13: 4 | AM13: 3 | AN13: =SUM(AK13:AM13) -> 10 | AO13: 4 | AP13: 3 | AQ13: 3 | AR13: =SUM(AO13:AQ13) -> 10 | AS13: 3 | AT13: 3 | AU13: 3 | AV13: =SUM(AS13:AU13) -> 9
A14: REQ-011 | B14: Authentication | C14: CAPTCHA Verification | D14: Medium | E14: 4 | F14: 3 | G14: 3 | H14: =SUM(E14:G14) -> 10 | I14: 3 | J14: 3 | K14: 3 | L14: =SUM(I14:K14) -> 9 | M14: 4 | N14: 4 | O14: 3 | P14: =SUM(M14:O14) -> 11 | Q14: 4 | R14: 3 | S14: 4 | T14: =SUM(Q14:S14) -> 11 | U14: 3 | V14: 3 | W14: 4 | X14: =SUM(U14:W14) -> 10 | Y14: 3 | Z14: 4 | AA14: 3 | AB14: =SUM(Y14:AA14) -> 10 | AC14: 3 | AD14: 3 | AE14: 4 | AF14: =SUM(AC14:AE14) -> 10 | AG14: 4 | AH14: 4 | AI14: 3 | AJ14: =SUM(AG14:AI14) -> 11 | AK14: 3 | AL14: 3 | AM14: 3 | AN14: =SUM(AK14:AM14) -> 9 | AO14: 3 | AP14: 4 | AQ14: 3 | AR14: =SUM(AO14:AQ14) -> 10 | AS14: 3 | AT14: 3 | AU14: 4 | AV14: =SUM(AS14:AU14) -> 10
A15: REQ-012 | B15: Authentication | C15: Email Verification After Registration | D15: Medium | E15: 3 | F15: 4 | G15: 3 | H15: =SUM(E15:G15) -> 10 | I15: 3 | J15: 3 | K15: 4 | L15: =SUM(I15:K15) -> 10 | M15: 4 | N15: 3 | O15: 4 | P15: =SUM(M15:O15) -> 11 | Q15: 3 | R15: 4 | S15: 3 | T15: =SUM(Q15:S15) -> 10 | U15: 3 | V15: 3 | W15: 3 | X15: =SUM(U15:W15) -> 9 | Y15: 3 | Z15: 4 | AA15: 4 | AB15: =SUM(Y15:AA15) -> 11 | AC15: 4 | AD15: 4 | AE15: 4 | AF15: =SUM(AC15:AE15) -> 12 | AG15: 3 | AH15: 3 | AI15: 3 | AJ15: =SUM(AG15:AI15) -> 9 | AK15: 4 | AL15: 4 | AM15: 4 | AN15: =SUM(AK15:AM15) -> 12 | AO15: 3 | AP15: 3 | AQ15: 3 | AR15: =SUM(AO15:AQ15) -> 9 | AS15: 3 | AT15: 2 | AU15: 3 | AV15: =SUM(AS15:AU15) -> 8
... A183: REQ-180 | B183: e-Governance | C183: Document Apostille Request | D183: Complex | E183: 3 | F183: 4 | G183: 4 | H183: =SUM(E183:G183) -> 11 | I183: 3 | J183: 2 | K183: 3 | L183: =SUM(I183:K183) -> 8 | M183: 3 | N183: 3 | O183: 3 | P183: =SUM(M183:O183) -> 9 | Q183: 3 | R183: 4 | S183: 4 | T183: =SUM(Q183:S183) -> 11 | U183: 3 | V183: 3 | W183: 3 | X183: =SUM(U183:W183) -> 9 | Y183: 3 | Z183: 3 | AA183: 3 | AB183: =SUM(Y183:AA183) -> 9 | AC183: 3 | AD183: 3 | AE183: 3 | AF183: =SUM(AC183:AE183) -> 9 | AG183: 3 | AH183: 3 | AI183: 2 | AJ183: =SUM(AG183:AI183) -> 8 | AK183: 3 | AL183: 4 | AM183: 2 | AN183: =SUM(AK183:AM183) -> 9 | AO183: 3 | AP183: 3 | AQ183: 3 | AR183: =SUM(AO183:AQ183) -> 9 | AS183: 3 | AT183: 3 | AU183: 2 | AV183: =SUM(AS183:AU183) -> 8

Sheet Annotator2_Scores
A1: SCOTC v3.0 — Annotator 2 Scores | 180 Requirements × 11 Models
A2: REQ ID | B2: Domain | C2: Requirement | D2: Complexity | E2: ChatGPT | I2: Gemini | M2: GPT-4o | Q2: Claude | U2: Llama 3.3 70B | Y2: Mistral Large 2 | AC2: DeepSeek-V3 | AG2: Grok-2 | AK2: Qwen2.5 72B | AO2: Command R+ | AS2: Gemma 2 27B
E3: C (1-5) | F3: R (1-5) | G3: TR (1-5) | H3: Total | I3: C (1-5) | J3: R (1-5) | K3: TR (1-5) | L3: Total | M3: C (1-5) | N3: R (1-5) | O3: TR (1-5) | P3: Total | Q3: C (1-5) | R3: R (1-5) | S3: TR (1-5) | T3: Total | U3: C (1-5) | V3: R (1-5) | W3: TR (1-5) | X3: Total | Y3: C (1-5) | Z3: R (1-5) | AA3: TR (1-5) | AB3: Total | AC3: C (1-5) | AD3: R (1-5) | AE3: TR (1-5) | AF3: Total | AG3: C (1-5) | AH3: R (1-5) | AI3: TR (1-5) | AJ3: Total | AK3: C (1-5) | AL3: R (1-5) | AM3: TR (1-5) | AN3: Total | AO3: C (1-5) | AP3: R (1-5) | AQ3: TR (1-5) | AR3: Total | AS3: C (1-5) | AT3: R (1-5) | AU3: TR (1-5) | AV3: Total
A4: REQ-001 | B4: Authentication | C4: User Registration | D4: Medium | E4: 3 | F4: 3 | G4: 3 | H4: =SUM(E4:G4) -> 9 | I4: 3 | J4: 4 | K4: 3 | L4: =SUM(I4:K4) -> 10 | M4: 3 | N4: 4 | O4: 4 | P4: =SUM(M4:O4) -> 11 | Q4: 4 | R4: 3 | S4: 3 | T4: =SUM(Q4:S4) -> 10 | U4: 3 | V4: 3 | W4: 3 | X4: =SUM(U4:W4) -> 9 | Y4: 4 | Z4: 3 | AA4: 3 | AB4: =SUM(Y4:AA4) -> 10 | AC4: 4 | AD4: 3 | AE4: 3 | AF4: =SUM(AC4:AE4) -> 10 | AG4: 4 | AH4: 4 | AI4: 3 | AJ4: =SUM(AG4:AI4) -> 11 | AK4: 4 | AL4: 3 | AM4: 3 | AN4: =SUM(AK4:AM4) -> 10 | AO4: 3 | AP4: 3 | AQ4: 3 | AR4: =SUM(AO4:AQ4) -> 9 | AS4: 3 | AT4: 3 | AU4: 3 | AV4: =SUM(AS4:AU4) -> 9
A5: REQ-002 | B5: Authentication | C5: User Login | D5: Simple | E5: 4 | F5: 3 | G5: 4 | H5: =SUM(E5:G5) -> 11 | I5: 3 | J5: 3 | K5: 3 | L5: =SUM(I5:K5) -> 9 | M5: 3 | N5: 4 | O5: 4 | P5: =SUM(M5:O5) -> 11 | Q5: 3 | R5: 4 | S5: 3 | T5: =SUM(Q5:S5) -> 10 | U5: 4 | V5: 4 | W5: 3 | X5: =SUM(U5:W5) -> 11 | Y5: 3 | Z5: 3 | AA5: 3 | AB5: =SUM(Y5:AA5) -> 9 | AC5: 4 | AD5: 3 | AE5: 4 | AF5: =SUM(AC5:AE5) -> 11 | AG5: 3 | AH5: 4 | AI5: 3 | AJ5: =SUM(AG5:AI5) -> 10 | AK5: 3 | AL5: 3 | AM5: 4 | AN5: =SUM(AK5:AM5) -> 10 | AO5: 4 | AP5: 4 | AQ5: 4 | AR5: =SUM(AO5:AQ5) -> 12 | AS5: 3 | AT5: 3 | AU5: 4 | AV5: =SUM(AS5:AU5) -> 10
A6: REQ-003 | B6: Authentication | C6: Password Reset via Email | D6: Medium | E6: 4 | F6: 3 | G6: 3 | H6: =SUM(E6:G6) -> 10 | I6: 3 | J6: 3 | K6: 3 | L6: =SUM(I6:K6) -> 9 | M6: 5 | N6: 4 | O6: 4 | P6: =SUM(M6:O6) -> 13 | Q6: 4 | R6: 4 | S6: 4 | T6: =SUM(Q6:S6) -> 12 | U6: 3 | V6: 4 | W6: 3 | X6: =SUM(U6:W6) -> 10 | Y6: 3 | Z6: 4 | AA6: 3 | AB6: =SUM(Y6:AA6) -> 10 | AC6: 3 | AD6: 4 | AE6: 4 | AF6: =SUM(AC6:AE6) -> 11 | AG6: 4 | AH6: 3 | AI6: 4 | AJ6: =SUM(AG6:AI6) -> 11 | AK6: 4 | AL6: 3 | AM6: 3 | AN6: =SUM(AK6:AM6) -> 10 | AO6: 3 | AP6: 3 | AQ6: 3 | AR6: =SUM(AO6:AQ6) -> 9 | AS6: 3 | AT6: 4 | AU6: 4 | AV6: =SUM(AS6:AU6) -> 11
A7: REQ-004 | B7: Authentication | C7: Password Reset via OTP | D7: Medium | E7: 3 | F7: 3 | G7: 3 | H7: =SUM(E7:G7) -> 9 | I7: 4 | J7: 3 | K7: 4 | L7: =SUM(I7:K7) -> 11 | M7: 4 | N7: 3 | O7: 3 | P7: =SUM(M7:O7) -> 10 | Q7: 3 | R7: 4 | S7: 3 | T7: =SUM(Q7:S7) -> 10 | U7: 3 | V7: 3 | W7: 4 | X7: =SUM(U7:W7) -> 10 | Y7: 4 | Z7: 4 | AA7: 3 | AB7: =SUM(Y7:AA7) -> 11 | AC7: 3 | AD7: 4 | AE7: 4 | AF7: =SUM(AC7:AE7) -> 11 | AG7: 4 | AH7: 3 | AI7: 3 | AJ7: =SUM(AG7:AI7) -> 10 | AK7: 4 | AL7: 4 | AM7: 4 | AN7: =SUM(AK7:AM7) -> 12 | AO7: 4 | AP7: 3 | AQ7: 3 | AR7: =SUM(AO7:AQ7) -> 10 | AS7: 3 | AT7: 3 | AU7: 3 | AV7: =SUM(AS7:AU7) -> 9
A8: REQ-005 | B8: Authentication | C8: Multi-Factor Authentication (MFA) | D8: Complex | E8: 3 | F8: 3 | G8: 3 | H8: =SUM(E8:G8) -> 9 | I8: 3 | J8: 4 | K8: 3 | L8: =SUM(I8:K8) -> 10 | M8: 4 | N8: 3 | O8: 4 | P8: =SUM(M8:O8) -> 11 | Q8: 4 | R8: 3 | S8: 3 | T8: =SUM(Q8:S8) -> 10 | U8: 4 | V8: 3 | W8: 3 | X8: =SUM(U8:W8) -> 10 | Y8: 3 | Z8: 4 | AA8: 3 | AB8: =SUM(Y8:AA8) -> 10 | AC8: 3 | AD8: 4 | AE8: 3 | AF8: =SUM(AC8:AE8) -> 10 | AG8: 3 | AH8: 4 | AI8: 3 | AJ8: =SUM(AG8:AI8) -> 10 | AK8: 3 | AL8: 4 | AM8: 2 | AN8: =SUM(AK8:AM8) -> 9 | AO8: 3 | AP8: 3 | AQ8: 2 | AR8: =SUM(AO8:AQ8) -> 8 | AS8: 3 | AT8: 3 | AU8: 2 | AV8: =SUM(AS8:AU8) -> 8
A9: REQ-006 | B9: Authentication | C9: Session Timeout | D9: Simple | E9: 4 | F9: 3 | G9: 3 | H9: =SUM(E9:G9) -> 10 | I9: 3 | J9: 3 | K9: 4 | L9: =SUM(I9:K9) -> 10 | M9: 3 | N9: 4 | O9: 3 | P9: =SUM(M9:O9) -> 10 | Q9: 3 | R9: 3 | S9: 4 | T9: =SUM(Q9:S9) -> 10 | U9: 3 | V9: 3 | W9: 4 | X9: =SUM(U9:W9) -> 10 | Y9: 4 | Z9: 3 | AA9: 3 | AB9: =SUM(Y9:AA9) -> 10 | AC9: 4 | AD9: 3 | AE9: 3 | AF9: =SUM(AC9:AE9) -> 10 | AG9: 3 | AH9: 4 | AI9: 4 | AJ9: =SUM(AG9:AI9) -> 11 | AK9: 4 | AL9: 3 | AM9: 4 | AN9: =SUM(AK9:AM9) -> 11 | AO9: 4 | AP9: 3 | AQ9: 3 | AR9: =SUM(AO9:AQ9) -> 10 | AS9: 3 | AT9: 3 | AU9: 3 | AV9: =SUM(AS9:AU9) -> 9
A10: REQ-007 | B10: Authentication | C10: Account Lockout After Failed Attempts | D10: Medium | E10: 4 | F10: 3 | G10: 3 | H10: =SUM(E10:G10) -> 10 | I10: 3 | J10: 4 | K10: 3 | L10: =SUM(I10:K10) -> 10 | M10: 3 | N10: 3 | O10: 3 | P10: =SUM(M10:O10) -> 9 | Q10: 4 | R10: 3 | S10: 3 | T10: =SUM(Q10:S10) -> 10 | U10: 4 | V10: 3 | W10: 4 | X10: =SUM(U10:W10) -> 11 | Y10: 4 | Z10: 4 | AA10: 4 | AB10: =SUM(Y10:AA10) -> 12 | AC10: 3 | AD10: 4 | AE10: 4 | AF10: =SUM(AC10:AE10) -> 11 | AG10: 4 | AH10: 4 | AI10: 3 | AJ10: =SUM(AG10:AI10) -> 11 | AK10: 4 | AL10: 3 | AM10: 3 | AN10: =SUM(AK10:AM10) -> 10 | AO10: 3 | AP10: 4 | AQ10: 3 | AR10: =SUM(AO10:AQ10) -> 10 | AS10: 3 | AT10: 3 | AU10: 4 | AV10: =SUM(AS10:AU10) -> 10
A11: REQ-008 | B11: Authentication | C11: Change Password | D11: Simple | E11: 3 | F11: 3 | G11: 4 | H11: =SUM(E11:G11) -> 10 | I11: 4 | J11: 3 | K11: 3 | L11: =SUM(I11:K11) -> 10 | M11: 4 | N11: 4 | O11: 4 | P11: =SUM(M11:O11) -> 12 | Q11: 4 | R11: 3 | S11: 3 | T11: =SUM(Q11:S11) -> 10 | U11: 4 | V11: 3 | W11: 4 | X11: =SUM(U11:W11) -> 11 | Y11: 4 | Z11: 3 | AA11: 3 | AB11: =SUM(Y11:AA11) -> 10 | AC11: 4 | AD11: 4 | AE11: 4 | AF11: =SUM(AC11:AE11) -> 12 | AG11: 4 | AH11: 4 | AI11: 3 | AJ11: =SUM(AG11:AI11) -> 11 | AK11: 4 | AL11: 3 | AM11: 4 | AN11: =SUM(AK11:AM11) -> 11 | AO11: 3 | AP11: 4 | AQ11: 3 | AR11: =SUM(AO11:AQ11) -> 10 | AS11: 3 | AT11: 3 | AU11: 4 | AV11: =SUM(AS11:AU11) -> 10
A12: REQ-009 | B12: Authentication | C12: Remember Me Functionality | D12: Medium | E12: 4 | F12: 3 | G12: 3 | H12: =SUM(E12:G12) -> 10 | I12: 3 | J12: 3 | K12: 4 | L12: =SUM(I12:K12) -> 10 | M12: 4 | N12: 3 | O12: 4 | P12: =SUM(M12:O12) -> 11 | Q12: 3 | R12: 4 | S12: 3 | T12: =SUM(Q12:S12) -> 10 | U12: 3 | V12: 3 | W12: 3 | X12: =SUM(U12:W12) -> 9 | Y12: 3 | Z12: 3 | AA12: 4 | AB12: =SUM(Y12:AA12) -> 10 | AC12: 3 | AD12: 4 | AE12: 4 | AF12: =SUM(AC12:AE12) -> 11 | AG12: 3 | AH12: 4 | AI12: 4 | AJ12: =SUM(AG12:AI12) -> 11 | AK12: 3 | AL12: 4 | AM12: 3 | AN12: =SUM(AK12:AM12) -> 10 | AO12: 4 | AP12: 3 | AQ12: 4 | AR12: =SUM(AO12:AQ12) -> 11 | AS12: 3 | AT12: 4 | AU12: 3 | AV12: =SUM(AS12:AU12) -> 10
A13: REQ-010 | B13: Authentication | C13: Logout from All Devices | D13: Medium | E13: 3 | F13: 4 | G13: 3 | H13: =SUM(E13:G13) -> 10 | I13: 3 | J13: 3 | K13: 3 | L13: =SUM(I13:K13) -> 9 | M13: 4 | N13: 4 | O13: 3 | P13: =SUM(M13:O13) -> 11 | Q13: 3 | R13: 3 | S13: 4 | T13: =SUM(Q13:S13) -> 10 | U13: 4 | V13: 4 | W13: 3 | X13: =SUM(U13:W13) -> 11 | Y13: 3 | Z13: 3 | AA13: 3 | AB13: =SUM(Y13:AA13) -> 9 | AC13: 4 | AD13: 3 | AE13: 4 | AF13: =SUM(AC13:AE13) -> 11 | AG13: 3 | AH13: 3 | AI13: 4 | AJ13: =SUM(AG13:AI13) -> 10 | AK13: 4 | AL13: 3 | AM13: 3 | AN13: =SUM(AK13:AM13) -> 10 | AO13: 3 | AP13: 3 | AQ13: 3 | AR13: =SUM(AO13:AQ13) -> 9 | AS13: 3 | AT13: 4 | AU13: 4 | AV13: =SUM(AS13:AU13) -> 11
A14: REQ-011 | B14: Authentication | C14: CAPTCHA Verification | D14: Medium | E14: 3 | F14: 3 | G14: 4 | H14: =SUM(E14:G14) -> 10 | I14: 3 | J14: 3 | K14: 3 | L14: =SUM(I14:K14) -> 9 | M14: 4 | N14: 4 | O14: 4 | P14: =SUM(M14:O14) -> 12 | Q14: 4 | R14: 3 | S14: 3 | T14: =SUM(Q14:S14) -> 10 | U14: 4 | V14: 4 | W14: 3 | X14: =SUM(U14:W14) -> 11 | Y14: 3 | Z14: 4 | AA14: 3 | AB14: =SUM(Y14:AA14) -> 10 | AC14: 4 | AD14: 4 | AE14: 3 | AF14: =SUM(AC14:AE14) -> 11 | AG14: 3 | AH14: 4 | AI14: 4 | AJ14: =SUM(AG14:AI14) -> 11 | AK14: 4 | AL14: 3 | AM14: 4 | AN14: =SUM(AK14:AM14) -> 11 | AO14: 4 | AP14: 3 | AQ14: 3 | AR14: =SUM(AO14:AQ14) -> 10 | AS14: 4 | AT14: 3 | AU14: 3 | AV14: =SUM(AS14:AU14) -> 10
A15: REQ-012 | B15: Authentication | C15: Email Verification After Registration | D15: Medium | E15: 3 | F15: 3 | G15: 3 | H15: =SUM(E15:G15) -> 9 | I15: 4 | J15: 3 | K15: 4 | L15: =SUM(I15:K15) -> 11 | M15: 3 | N15: 3 | O15: 4 | P15: =SUM(M15:O15) -> 10 | Q15: 3 | R15: 4 | S15: 4 | T15: =SUM(Q15:S15) -> 11 | U15: 3 | V15: 3 | W15: 4 | X15: =SUM(U15:W15) -> 10 | Y15: 4 | Z15: 3 | AA15: 3 | AB15: =SUM(Y15:AA15) -> 10 | AC15: 4 | AD15: 4 | AE15: 4 | AF15: =SUM(AC15:AE15) -> 12 | AG15: 4 | AH15: 3 | AI15: 4 | AJ15: =SUM(AG15:AI15) -> 11 | AK15: 4 | AL15: 4 | AM15: 3 | AN15: =SUM(AK15:AM15) -> 11 | AO15: 4 | AP15: 3 | AQ15: 2 | AR15: =SUM(AO15:AQ15) -> 9 | AS15: 3 | AT15: 3 | AU15: 3 | AV15: =SUM(AS15:AU15) -> 9
... A183: REQ-180 | B183: e-Governance | C183: Document Apostille Request | D183: Complex | E183: 3 | F183: 3 | G183: 3 | H183: =SUM(E183:G183) -> 9 | I183: 3 | J183: 3 | K183: 3 | L183: =SUM(I183:K183) -> 9 | M183: 3 | N183: 4 | O183: 3 | P183: =SUM(M183:O183) -> 10 | Q183: 3 | R183: 3 | S183: 3 | T183: =SUM(Q183:S183) -> 9 | U183: 3 | V183: 3 | W183: 2 | X183: =SUM(U183:W183) -> 8 | Y183: 2 | Z183: 4 | AA183: 4 | AB183: =SUM(Y183:AA183) -> 10 | AC183: 3 | AD183: 4 | AE183: 3 | AF183: =SUM(AC183:AE183) -> 10 | AG183: 3 | AH183: 3 | AI183: 3 | AJ183: =SUM(AG183:AI183) -> 9 | AK183: 3 | AL183: 3 | AM183: 3 | AN183: =SUM(AK183:AM183) -> 9 | AO183: 3 | AP183: 4 | AQ183: 2 | AR183: =SUM(AO183:AQ183) -> 9 | AS183: 3 | AT183: 3 | AU183: 3 | AV183: =SUM(AS183:AU183) -> 9

Sheet Annotator3_Scores
A1: SCOTC v3.0 — Annotator 3 Scores | 180 Requirements × 11 Models
A2: REQ ID | B2: Domain | C2: Requirement | D2: Complexity | E2: ChatGPT | I2: Gemini | M2: GPT-4o | Q2: Claude | U2: Llama 3.3 70B | Y2: Mistral Large 2 | AC2: DeepSeek-V3 | AG2: Grok-2 | AK2: Qwen2.5 72B | AO2: Command R+ | AS2: Gemma 2 27B
E3: C (1-5) | F3: R (1-5) | G3: TR (1-5) | H3: Total | I3: C (1-5) | J3: R (1-5) | K3: TR (1-5) | L3: Total | M3: C (1-5) | N3: R (1-5) | O3: TR (1-5) | P3: Total | Q3: C (1-5) | R3: R (1-5) | S3: TR (1-5) | T3: Total | U3: C (1-5) | V3: R (1-5) | W3: TR (1-5) | X3: Total | Y3: C (1-5) | Z3: R (1-5) | AA3: TR (1-5) | AB3: Total | AC3: C (1-5) | AD3: R (1-5) | AE3: TR (1-5) | AF3: Total | AG3: C (1-5) | AH3: R (1-5) | AI3: TR (1-5) | AJ3: Total | AK3: C (1-5) | AL3: R (1-5) | AM3: TR (1-5) | AN3: Total | AO3: C (1-5) | AP3: R (1-5) | AQ3: TR (1-5) | AR3: Total | AS3: C (1-5) | AT3: R (1-5) | AU3: TR (1-5) | AV3: Total
A4: REQ-001 | B4: Authentication | C4: User Registration | D4: Medium | E4: 4 | F4: 3 | G4: 3 | H4: =SUM(E4:G4) -> 10 | I4: 3 | J4: 3 | K4: 3 | L4: =SUM(I4:K4) -> 9 | M4: 4 | N4: 4 | O4: 4 | P4: =SUM(M4:O4) -> 12 | Q4: 4 | R4: 3 | S4: 4 | T4: =SUM(Q4:S4) -> 11 | U4: 3 | V4: 3 | W4: 4 | X4: =SUM(U4:W4) -> 10 | Y4: 3 | Z4: 4 | AA4: 3 | AB4: =SUM(Y4:AA4) -> 10 | AC4: 4 | AD4: 4 | AE4: 4 | AF4: =SUM(AC4:AE4) -> 12 | AG4: 4 | AH4: 4 | AI4: 3 | AJ4: =SUM(AG4:AI4) -> 11 | AK4: 4 | AL4: 3 | AM4: 4 | AN4: =SUM(AK4:AM4) -> 11 | AO4: 3 | AP4: 3 | AQ4: 4 | AR4: =SUM(AO4:AQ4) -> 10 | AS4: 4 | AT4: 3 | AU4: 3 | AV4: =SUM(AS4:AU4) -> 10
A5: REQ-002 | B5: Authentication | C5: User Login | D5: Simple | E5: 3 | F5: 4 | G5: 3 | H5: =SUM(E5:G5) -> 10 | I5: 3 | J5: 3 | K5: 3 | L5: =SUM(I5:K5) -> 9 | M5: 3 | N5: 3 | O5: 3 | P5: =SUM(M5:O5) -> 9 | Q5: 4 | R5: 4 | S5: 4 | T5: =SUM(Q5:S5) -> 12 | U5: 3 | V5: 3 | W5: 3 | X5: =SUM(U5:W5) -> 9 | Y5: 3 | Z5: 3 | AA5: 3 | AB5: =SUM(Y5:AA5) -> 9 | AC5: 4 | AD5: 3 | AE5: 4 | AF5: =SUM(AC5:AE5) -> 11 | AG5: 4 | AH5: 3 | AI5: 4 | AJ5: =SUM(AG5:AI5) -> 11 | AK5: 3 | AL5: 3 | AM5: 3 | AN5: =SUM(AK5:AM5) -> 9 | AO5: 4 | AP5: 4 | AQ5: 3 | AR5: =SUM(AO5:AQ5) -> 11 | AS5: 4 | AT5: 4 | AU5: 3 | AV5: =SUM(AS5:AU5) -> 11
A6: REQ-003 | B6: Authentication | C6: Password Reset via Email | D6: Medium | E6: 4 | F6: 3 | G6: 3 | H6: =SUM(E6:G6) -> 10 | I6: 3 | J6: 3 | K6: 3 | L6: =SUM(I6:K6) -> 9 | M6: 4 | N6: 4 | O6: 4 | P6: =SUM(M6:O6) -> 12 | Q6: 3 | R6: 4 | S6: 4 | T6: =SUM(Q6:S6) -> 11 | U6: 4 | V6: 4 | W6: 3 | X6: =SUM(U6:W6) -> 11 | Y6: 3 | Z6: 3 | AA6: 3 | AB6: =SUM(Y6:AA6) -> 9 | AC6: 3 | AD6: 3 | AE6: 4 | AF6: =SUM(AC6:AE6) -> 10 | AG6: 3 | AH6: 3 | AI6: 4 | AJ6: =SUM(AG6:AI6) -> 10 | AK6: 4 | AL6: 4 | AM6: 3 | AN6: =SUM(AK6:AM6) -> 11 | AO6: 3 | AP6: 3 | AQ6: 3 | AR6: =SUM(AO6:AQ6) -> 9 | AS6: 3 | AT6: 3 | AU6: 3 | AV6: =SUM(AS6:AU6) -> 9
A7: REQ-004 | B7: Authentication | C7: Password Reset via OTP | D7: Medium | E7: 3 | F7: 3 | G7: 3 | H7: =SUM(E7:G7) -> 9 | I7: 4 | J7: 4 | K7: 3 | L7: =SUM(I7:K7) -> 11 | M7: 4 | N7: 4 | O7: 3 | P7: =SUM(M7:O7) -> 11 | Q7: 3 | R7: 3 | S7: 4 | T7: =SUM(Q7:S7) -> 10 | U7: 4 | V7: 4 | W7: 3 | X7: =SUM(U7:W7) -> 11 | Y7: 3 | Z7: 4 | AA7: 4 | AB7: =SUM(Y7:AA7) -> 11 | AC7: 3 | AD7: 3 | AE7: 4 | AF7: =SUM(AC7:AE7) -> 10 | AG7: 3 | AH7: 4 | AI7: 4 | AJ7: =SUM(AG7:AI7) -> 11 | AK7: 3 | AL7: 3 | AM7: 3 | AN7: =SUM(AK7:AM7) -> 9 | AO7: 3 | AP7: 3 | AQ7: 3 | AR7: =SUM(AO7:AQ7) -> 9 | AS7: 3 | AT7: 4 | AU7: 3 | AV7: =SUM(AS7:AU7) -> 10
A8: REQ-005 | B8: Authentication | C8: Multi-Factor Authentication (MFA) | D8: Complex | E8: 3 | F8: 3 | G8: 2 | H8: =SUM(E8:G8) -> 8 | I8: 2 | J8: 2 | K8: 3 | L8: =SUM(I8:K8) -> 7 | M8: 3 | N8: 3 | O8: 4 | P8: =SUM(M8:O8) -> 10 | Q8: 4 | R8: 4 | S8: 3 | T8: =SUM(Q8:S8) -> 11 | U8: 3 | V8: 3 | W8: 4 | X8: =SUM(U8:W8) -> 10 | Y8: 3 | Z8: 3 | AA8: 3 | AB8: =SUM(Y8:AA8) -> 9 | AC8: 4 | AD8: 3 | AE8: 4 | AF8: =SUM(AC8:AE8) -> 11 | AG8: 2 | AH8: 3 | AI8: 3 | AJ8: =SUM(AG8:AI8) -> 8 | AK8: 3 | AL8: 3 | AM8: 3 | AN8: =SUM(AK8:AM8) -> 9 | AO8: 3 | AP8: 3 | AQ8: 2 | AR8: =SUM(AO8:AQ8) -> 8 | AS8: 2 | AT8: 3 | AU8: 2 | AV8: =SUM(AS8:AU8) -> 7
A9: REQ-006 | B9: Authentication | C9: Session Timeout | D9: Simple | E9: 3 | F9: 3 | G9: 4 | H9: =SUM(E9:G9) -> 10 | I9: 4 | J9: 3 | K9: 3 | L9: =SUM(I9:K9) -> 10 | M9: 4 | N9: 4 | O9: 4 | P9: =SUM(M9:O9) -> 12 | Q9: 3 | R9: 3 | S9: 4 | T9: =SUM(Q9:S9) -> 10 | U9: 4 | V9: 4 | W9: 3 | X9: =SUM(U9:W9) -> 11 | Y9: 3 | Z9: 3 | AA9: 4 | AB9: =SUM(Y9:AA9) -> 10 | AC9: 3 | AD9: 3 | AE9: 4 | AF9: =SUM(AC9:AE9) -> 10 | AG9: 4 | AH9: 3 | AI9: 4 | AJ9: =SUM(AG9:AI9) -> 11 | AK9: 4 | AL9: 4 | AM9: 3 | AN9: =SUM(AK9:AM9) -> 11 | AO9: 4 | AP9: 4 | AQ9: 3 | AR9: =SUM(AO9:AQ9) -> 11 | AS9: 4 | AT9: 3 | AU9: 3 | AV9: =SUM(AS9:AU9) -> 10
A10: REQ-007 | B10: Authentication | C10: Account Lockout After Failed Attempts | D10: Medium | E10: 4 | F10: 3 | G10: 3 | H10: =SUM(E10:G10) -> 10 | I10: 3 | J10: 3 | K10: 2 | L10: =SUM(I10:K10) -> 8 | M10: 3 | N10: 4 | O10: 4 | P10: =SUM(M10:O10) -> 11 | Q10: 3 | R10: 3 | S10: 4 | T10: =SUM(Q10:S10) -> 10 | U10: 3 | V10: 3 | W10: 3 | X10: =SUM(U10:W10) -> 9 | Y10: 4 | Z10: 3 | AA10: 3 | AB10: =SUM(Y10:AA10) -> 10 | AC10: 4 | AD10: 3 | AE10: 4 | AF10: =SUM(AC10:AE10) -> 11 | AG10: 4 | AH10: 4 | AI10: 3 | AJ10: =SUM(AG10:AI10) -> 11 | AK10: 3 | AL10: 4 | AM10: 3 | AN10: =SUM(AK10:AM10) -> 10 | AO10: 3 | AP10: 4 | AQ10: 4 | AR10: =SUM(AO10:AQ10) -> 11 | AS10: 3 | AT10: 3 | AU10: 3 | AV10: =SUM(AS10:AU10) -> 9
A11: REQ-008 | B11: Authentication | C11: Change Password | D11: Simple | E11: 4 | F11: 4 | G11: 4 | H11: =SUM(E11:G11) -> 12 | I11: 3 | J11: 4 | K11: 3 | L11: =SUM(I11:K11) -> 10 | M11: 3 | N11: 3 | O11: 4 | P11: =SUM(M11:O11) -> 10 | Q11: 4 | R11: 3 | S11: 4 | T11: =SUM(Q11:S11) -> 11 | U11: 3 | V11: 3 | W11: 4 | X11: =SUM(U11:W11) -> 10 | Y11: 3 | Z11: 3 | AA11: 3 | AB11: =SUM(Y11:AA11) -> 9 | AC11: 3 | AD11: 4 | AE11: 3 | AF11: =SUM(AC11:AE11) -> 10 | AG11: 3 | AH11: 4 | AI11: 3 | AJ11: =SUM(AG11:AI11) -> 10 | AK11: 3 | AL11: 4 | AM11: 3 | AN11: =SUM(AK11:AM11) -> 10 | AO11: 4 | AP11: 3 | AQ11: 2 | AR11: =SUM(AO11:AQ11) -> 9 | AS11: 3 | AT11: 3 | AU11: 4 | AV11: =SUM(AS11:AU11) -> 10
A12: REQ-009 | B12: Authentication | C12: Remember Me Functionality | D12: Medium | E12: 3 | F12: 3 | G12: 4 | H12: =SUM(E12:G12) -> 10 | I12: 2 | J12: 4 | K12: 3 | L12: =SUM(I12:K12) -> 9 | M12: 4 | N12: 4 | O12: 4 | P12: =SUM(M12:O12) -> 12 | Q12: 4 | R12: 4 | S12: 3 | T12: =SUM(Q12:S12) -> 11 | U12: 3 | V12: 3 | W12: 3 | X12: =SUM(U12:W12) -> 9 | Y12: 3 | Z12: 3 | AA12: 3 | AB12: =SUM(Y12:AA12) -> 9 | AC12: 4 | AD12: 4 | AE12: 3 | AF12: =SUM(AC12:AE12) -> 11 | AG12: 3 | AH12: 3 | AI12: 3 | AJ12: =SUM(AG12:AI12) -> 9 | AK12: 3 | AL12: 4 | AM12: 3 | AN12: =SUM(AK12:AM12) -> 10 | AO12: 3 | AP12: 3 | AQ12: 3 | AR12: =SUM(AO12:AQ12) -> 9 | AS12: 3 | AT12: 4 | AU12: 3 | AV12: =SUM(AS12:AU12) -> 10
A13: REQ-010 | B13: Authentication | C13: Logout from All Devices | D13: Medium | E13: 3 | F13: 3 | G13: 4 | H13: =SUM(E13:G13) -> 10 | I13: 3 | J13: 3 | K13: 4 | L13: =SUM(I13:K13) -> 10 | M13: 4 | N13: 4 | O13: 4 | P13: =SUM(M13:O13) -> 12 | Q13: 4 | R13: 3 | S13: 4 | T13: =SUM(Q13:S13) -> 11 | U13: 3 | V13: 3 | W13: 3 | X13: =SUM(U13:W13) -> 9 | Y13: 3 | Z13: 3 | AA13: 3 | AB13: =SUM(Y13:AA13) -> 9 | AC13: 3 | AD13: 3 | AE13: 4 | AF13: =SUM(AC13:AE13) -> 10 | AG13: 3 | AH13: 3 | AI13: 3 | AJ13: =SUM(AG13:AI13) -> 9 | AK13: 4 | AL13: 3 | AM13: 4 | AN13: =SUM(AK13:AM13) -> 11 | AO13: 3 | AP13: 4 | AQ13: 3 | AR13: =SUM(AO13:AQ13) -> 10 | AS13: 3 | AT13: 2 | AU13: 3 | AV13: =SUM(AS13:AU13) -> 8
A14: REQ-011 | B14: Authentication | C14: CAPTCHA Verification | D14: Medium | E14: 3 | F14: 3 | G14: 3 | H14: =SUM(E14:G14) -> 9 | I14: 3 | J14: 4 | K14: 3 | L14: =SUM(I14:K14) -> 10 | M14: 4 | N14: 3 | O14: 4 | P14: =SUM(M14:O14) -> 11 | Q14: 4 | R14: 3 | S14: 3 | T14: =SUM(Q14:S14) -> 10 | U14: 4 | V14: 4 | W14: 3 | X14: =SUM(U14:W14) -> 11 | Y14: 3 | Z14: 3 | AA14: 3 | AB14: =SUM(Y14:AA14) -> 9 | AC14: 4 | AD14: 3 | AE14: 4 | AF14: =SUM(AC14:AE14) -> 11 | AG14: 4 | AH14: 4 | AI14: 4 | AJ14: =SUM(AG14:AI14) -> 12 | AK14: 3 | AL14: 3 | AM14: 3 | AN14: =SUM(AK14:AM14) -> 9 | AO14: 4 | AP14: 3 | AQ14: 3 | AR14: =SUM(AO14:AQ14) -> 10 | AS14: 3 | AT14: 3 | AU14: 3 | AV14: =SUM(AS14:AU14) -> 9
A15: REQ-012 | B15: Authentication | C15: Email Verification After Registration | D15: Medium | E15: 3 | F15: 3 | G15: 4 | H15: =SUM(E15:G15) -> 10 | I15: 4 | J15: 4 | K15: 3 | L15: =SUM(I15:K15) -> 11 | M15: 3 | N15: 4 | O15: 4 | P15: =SUM(M15:O15) -> 11 | Q15: 3 | R15: 3 | S15: 3 | T15: =SUM(Q15:S15) -> 9 | U15: 3 | V15: 3 | W15: 3 | X15: =SUM(U15:W15) -> 9 | Y15: 4 | Z15: 4 | AA15: 3 | AB15: =SUM(Y15:AA15) -> 11 | AC15: 4 | AD15: 4 | AE15: 4 | AF15: =SUM(AC15:AE15) -> 12 | AG15: 3 | AH15: 4 | AI15: 4 | AJ15: =SUM(AG15:AI15) -> 11 | AK15: 4 | AL15: 3 | AM15: 3 | AN15: =SUM(AK15:AM15) -> 10 | AO15: 3 | AP15: 3 | AQ15: 4 | AR15: =SUM(AO15:AQ15) -> 10 | AS15: 3 | AT15: 2 | AU15: 3 | AV15: =SUM(AS15:AU15) -> 8
... A183: REQ-180 | B183: e-Governance | C183: Document Apostille Request | D183: Complex | E183: 3 | F183: 3 | G183: 2 | H183: =SUM(E183:G183) -> 8 | I183: 3 | J183: 3 | K183: 3 | L183: =SUM(I183:K183) -> 9 | M183: 4 | N183: 4 | O183: 4 | P183: =SUM(M183:O183) -> 12 | Q183: 3 | R183: 4 | S183: 4 | T183: =SUM(Q183:S183) -> 11 | U183: 3 | V183: 3 | W183: 2 | X183: =SUM(U183:W183) -> 8 | Y183: 3 | Z183: 2 | AA183: 3 | AB183: =SUM(Y183:AA183) -> 8 | AC183: 3 | AD183: 3 | AE183: 2 | AF183: =SUM(AC183:AE183) -> 8 | AG183: 2 | AH183: 3 | AI183: 3 | AJ183: =SUM(AG183:AI183) -> 8 | AK183: 3 | AL183: 3 | AM183: 4 | AN183: =SUM(AK183:AM183) -> 10 | AO183: 3 | AP183: 3 | AQ183: 2 | AR183: =SUM(AO183:AQ183) -> 8 | AS183: 2 | AT183: 3 | AU183: 3 | AV183: =SUM(AS183:AU183) -> 8

Sheet IRR_and_Summary
A1: SCOTC v3.0 — IRR & Summary | Averaged across 3 Annotators | 180 Requirements × 11 Models
A2: REQ_ID | B2: Domain | C2: Requirement | D2: Complexity | E2: Model | F2: Avg_Completeness | G2: Avg_Relevance | H2: Avg_Traceability | I2: Avg_Total | J2: Req_Count
A3: REQ-001 | B3: Authentication | C3: User Registration | D3: Medium | E3: ChatGPT | F3: =AVERAGE(Annotator1_Scores!E4,Annotator2_Scores!E4,Annotator3_Scores!E4) -> 3.6666667 | G3: =AVERAGE(Annotator1_Scores!F4,Annotator2_Scores!F4,Annotator3_Scores!F4) -> 3 | H3: =AVERAGE(Annotator1_Scores!G4,Annotator2_Scores!G4,Annotator3_Scores!G4) -> 3 | I3: =SUM(F3:H3) -> 9.6666667 | J3: 20
A4: REQ-001 | B4: Authentication | C4: User Registration | D4: Medium | E4: Gemini | F4: =AVERAGE(Annotator1_Scores!I4,Annotator2_Scores!I4,Annotator3_Scores!I4) -> 3 | G4: =AVERAGE(Annotator1_Scores!J4,Annotator2_Scores!J4,Annotator3_Scores!J4) -> 3.6666667 | H4: =AVERAGE(Annotator1_Scores!K4,Annotator2_Scores!K4,Annotator3_Scores!K4) -> 3 | I4: =SUM(F4:H4) -> 9.6666667 | J4: 20
A5: REQ-001 | B5: Authentication | C5: User Registration | D5: Medium | E5: GPT-4o | F5: =AVERAGE(Annotator1_Scores!M4,Annotator2_Scores!M4,Annotator3_Scores!M4) -> 3.6666667 | G5: =AVERAGE(Annotator1_Scores!N4,Annotator2_Scores!N4,Annotator3_Scores!N4) -> 3.6666667 | H5: =AVERAGE(Annotator1_Scores!O4,Annotator2_Scores!O4,Annotator3_Scores!O4) -> 3.6666667 | I5: =SUM(F5:H5) -> 11 | J5: 20
A6: REQ-001 | B6: Authentication | C6: User Registration | D6: Medium | E6: Claude | F6: =AVERAGE(Annotator1_Scores!Q4,Annotator2_Scores!Q4,Annotator3_Scores!Q4) -> 3.6666667 | G6: =AVERAGE(Annotator1_Scores!R4,Annotator2_Scores!R4,Annotator3_Scores!R4) -> 3 | H6: =AVERAGE(Annotator1_Scores!S4,Annotator2_Scores!S4,Annotator3_Scores!S4) -> 3.3333333 | I6: =SUM(F6:H6) -> 10 | J6: 20
A7: REQ-001 | B7: Authentication | C7: User Registration | D7: Medium | E7: Llama 3.3 70B | F7: =AVERAGE(Annotator1_Scores!U4,Annotator2_Scores!U4,Annotator3_Scores!U4) -> 3 | G7: =AVERAGE(Annotator1_Scores!V4,Annotator2_Scores!V4,Annotator3_Scores!V4) -> 3 | H7: =AVERAGE(Annotator1_Scores!W4,Annotator2_Scores!W4,Annotator3_Scores!W4) -> 3.3333333 | I7: =SUM(F7:H7) -> 9.3333333 | J7: 20
A8: REQ-001 | B8: Authentication | C8: User Registration | D8: Medium | E8: Mistral Large 2 | F8: =AVERAGE(Annotator1_Scores!Y4,Annotator2_Scores!Y4,Annotator3_Scores!Y4) -> 3.3333333 | G8: =AVERAGE(Annotator1_Scores!Z4,Annotator2_Scores!Z4,Annotator3_Scores!Z4) -> 3.3333333 | H8: =AVERAGE(Annotator1_Scores!AA4,Annotator2_Scores!AA4,Annotator3_Scores!AA4) -> 3 | I8: =SUM(F8:H8) -> 9.6666667 | J8: 20
A9: REQ-001 | B9: Authentication | C9: User Registration | D9: Medium | E9: DeepSeek-V3 | F9: =AVERAGE(Annotator1_Scores!AC4,Annotator2_Scores!AC4,Annotator3_Scores!AC4) -> 3.6666667 | G9: =AVERAGE(Annotator1_Scores!AD4,Annotator2_Scores!AD4,Annotator3_Scores!AD4) -> 3.6666667 | H9: =AVERAGE(Annotator1_Scores!AE4,Annotator2_Scores!AE4,Annotator3_Scores!AE4) -> 3.3333333 | I9: =SUM(F9:H9) -> 10.666667 | J9: 20
A10: REQ-001 | B10: Authentication | C10: User Registration | D10: Medium | E10: Grok-2 | F10: =AVERAGE(Annotator1_Scores!AG4,Annotator2_Scores!AG4,Annotator3_Scores!AG4) -> 4 | G10: =AVERAGE(Annotator1_Scores!AH4,Annotator2_Scores!AH4,Annotator3_Scores!AH4) -> 3.6666667 | H10: =AVERAGE(Annotator1_Scores!AI4,Annotator2_Scores!AI4,Annotator3_Scores!AI4) -> 3 | I10: =SUM(F10:H10) -> 10.666667 | J10: 20
A11: REQ-001 | B11: Authentication | C11: User Registration | D11: Medium | E11: Qwen2.5 72B | F11: =AVERAGE(Annotator1_Scores!AK4,Annotator2_Scores!AK4,Annotator3_Scores!AK4) -> 4 | G11: =AVERAGE(Annotator1_Scores!AL4,Annotator2_Scores!AL4,Annotator3_Scores!AL4) -> 3 | H11: =AVERAGE(Annotator1_Scores!AM4,Annotator2_Scores!AM4,Annotator3_Scores!AM4) -> 3.3333333 | I11: =SUM(F11:H11) -> 10.333333 | J11: 20
A12: REQ-001 | B12: Authentication | C12: User Registration | D12: Medium | E12: Command R+ | F12: =AVERAGE(Annotator1_Scores!AO4,Annotator2_Scores!AO4,Annotator3_Scores!AO4) -> 3 | G12: =AVERAGE(Annotator1_Scores!AP4,Annotator2_Scores!AP4,Annotator3_Scores!AP4) -> 3 | H12: =AVERAGE(Annotator1_Scores!AQ4,Annotator2_Scores!AQ4,Annotator3_Scores!AQ4) -> 3.3333333 | I12: =SUM(F12:H12) -> 9.3333333 | J12: 20
A13: REQ-001 | B13: Authentication | C13: User Registration | D13: Medium | E13: Gemma 2 27B | F13: =AVERAGE(Annotator1_Scores!AS4,Annotator2_Scores!AS4,Annotator3_Scores!AS4) -> 3.3333333 | G13: =AVERAGE(Annotator1_Scores!AT4,Annotator2_Scores!AT4,Annotator3_Scores!AT4) -> 3 | H13: =AVERAGE(Annotator1_Scores!AU4,Annotator2_Scores!AU4,Annotator3_Scores!AU4) -> 3 | I13: =SUM(F13:H13) -> 9.3333333 | J13: 20
A14: REQ-002 | B14: Authentication | C14: User Login | D14: Simple | E14: ChatGPT | F14: =AVERAGE(Annotator1_Scores!E5,Annotator2_Scores!E5,Annotator3_Scores!E5) -> 3.3333333 | G14: =AVERAGE(Annotator1_Scores!F5,Annotator2_Scores!F5,Annotator3_Scores!F5) -> 3.3333333 | H14: =AVERAGE(Annotator1_Scores!G5,Annotator2_Scores!G5,Annotator3_Scores!G5) -> 3.3333333 | I14: =SUM(F14:H14) -> 10 | J14: 20
A15: REQ-002 | B15: Authentication | C15: User Login | D15: Simple | E15: Gemini | F15: =AVERAGE(Annotator1_Scores!I5,Annotator2_Scores!I5,Annotator3_Scores!I5) -> 3 | G15: =AVERAGE(Annotator1_Scores!J5,Annotator2_Scores!J5,Annotator3_Scores!J5) -> 3 | H15: =AVERAGE(Annotator1_Scores!K5,Annotator2_Scores!K5,Annotator3_Scores!K5) -> 3 | I15: =SUM(F15:H15) -> 9 | J15: 20
A16: REQ-002 | B16: Authentication | C16: User Login | D16: Simple | E16: GPT-4o | F16: =AVERAGE(Annotator1_Scores!M5,Annotator2_Scores!M5,Annotator3_Scores!M5) -> 3.3333333 | G16: =AVERAGE(Annotator1_Scores!N5,Annotator2_Scores!N5,Annotator3_Scores!N5) -> 3.3333333 | H16: =AVERAGE(Annotator1_Scores!O5,Annotator2_Scores!O5,Annotator3_Scores!O5) -> 3.6666667 | I16: =SUM(F16:H16) -> 10.333333 | J16: 20
A17: REQ-002 | B17: Authentication | C17: User Login | D17: Simple | E17: Claude | F17: =AVERAGE(Annotator1_Scores!Q5,Annotator2_Scores!Q5,Annotator3_Scores!Q5) -> 3.6666667 | G17: =AVERAGE(Annotator1_Scores!R5,Annotator2_Scores!R5,Annotator3_Scores!R5) -> 3.6666667 | H17: =AVERAGE(Annotator1_Scores!S5,Annotator2_Scores!S5,Annotator3_Scores!S5) -> 3.3333333 | I17: =SUM(F17:H17) -> 10.666667 | J17: 20
A18: REQ-002 | B18: Authentication | C18: User Login | D18: Simple | E18: Llama 3.3 70B | F18: =AVERAGE(Annotator1_Scores!U5,Annotator2_Scores!U5,Annotator3_Scores!U5) -> 3.6666667 | G18: =AVERAGE(Annotator1_Scores!V5,Annotator2_Scores!V5,Annotator3_Scores!V5) -> 3.6666667 | H18: =AVERAGE(Annotator1_Scores!W5,Annotator2_Scores!W5,Annotator3_Scores!W5) -> 3.3333333 | I18: =SUM(F18:H18) -> 10.666667 | J18: 20
A19: REQ-002 | B19: Authentication | C19: User Login | D19: Simple | E19: Mistral Large 2 | F19: =AVERAGE(Annotator1_Scores!Y5,Annotator2_Scores!Y5,Annotator3_Scores!Y5) -> 3 | G19: =AVERAGE(Annotator1_Scores!Z5,Annotator2_Scores!Z5,Annotator3_Scores!Z5) -> 3.3333333 | H19: =AVERAGE(Annotator1_Scores!AA5,Annotator2_Scores!AA5,Annotator3_Scores!AA5) -> 3 | I19: =SUM(F19:H19) -> 9.3333333 | J19: 20
A20: REQ-002 | B20: Authentication | C20: User Login | D20: Simple | E20: DeepSeek-V3 | F20: =AVERAGE(Annotator1_Scores!AC5,Annotator2_Scores!AC5,Annotator3_Scores!AC5) -> 3.6666667 | G20: =AVERAGE(Annotator1_Scores!AD5,Annotator2_Scores!AD5,Annotator3_Scores!AD5) -> 3.3333333 | H20: =AVERAGE(Annotator1_Scores!AE5,Annotator2_Scores!AE5,Annotator3_Scores!AE5) -> 4 | I20: =SUM(F20:H20) -> 11 | J20: 20
A21: REQ-002 | B21: Authentication | C21: User Login | D21: Simple | E21: Grok-2 | F21: =AVERAGE(Annotator1_Scores!AG5,Annotator2_Scores!AG5,Annotator3_Scores!AG5) -> 3.3333333 | G21: =AVERAGE(Annotator1_Scores!AH5,Annotator2_Scores!AH5,Annotator3_Scores!AH5) -> 3.3333333 | H21: =AVERAGE(Annotator1_Scores!AI5,Annotator2_Scores!AI5,Annotator3_Scores!AI5) -> 3.3333333 | I21: =SUM(F21:H21) -> 10 | J21: 20
A22: REQ-002 | B22: Authentication | C22: User Login | D22: Simple | E22: Qwen2.5 72B | F22: =AVERAGE(Annotator1_Scores!AK5,Annotator2_Scores!AK5,Annotator3_Scores!AK5) -> 3 | G22: =AVERAGE(Annotator1_Scores!AL5,Annotator2_Scores!AL5,Annotator3_Scores!AL5) -> 3.3333333 | H22: =AVERAGE(Annotator1_Scores!AM5,Annotator2_Scores!AM5,Annotator3_Scores!AM5) -> 3.6666667 | I22: =SUM(F22:H22) -> 10 | J22: 20
A23: REQ-002 | B23: Authentication | C23: User Login | D23: Simple | E23: Command R+ | F23: =AVERAGE(Annotator1_Scores!AO5,Annotator2_Scores!AO5,Annotator3_Scores!AO5) -> 4 | G23: =AVERAGE(Annotator1_Scores!AP5,Annotator2_Scores!AP5,Annotator3_Scores!AP5) -> 4 | H23: =AVERAGE(Annotator1_Scores!AQ5,Annotator2_Scores!AQ5,Annotator3_Scores!AQ5) -> 3.3333333 | I23: =SUM(F23:H23) -> 11.333333 | J23: 20
A24: REQ-002 | B24: Authentication | C24: User Login | D24: Simple | E24: Gemma 2 27B | F24: =AVERAGE(Annotator1_Scores!AS5,Annotator2_Scores!AS5,Annotator3_Scores!AS5) -> 3.3333333 | G24: =AVERAGE(Annotator1_Scores!AT5,Annotator2_Scores!AT5,Annotator3_Scores!AT5) -> 3.3333333 | H24: =AVERAGE(Annotator1_Scores!AU5,Annotator2_Scores!AU5,Annotator3_Scores!AU5) -> 3.3333333 | I24: =SUM(F24:H24) -> 10 | J24: 20
A25: REQ-003 | B25: Authentication | C25: Password Reset via Email | D25: Medium | E25: ChatGPT | F25: =AVERAGE(Annotator1_Scores!E6,Annotator2_Scores!E6,Annotator3_Scores!E6) -> 4 | G25: =AVERAGE(Annotator1_Scores!F6,Annotator2_Scores!F6,Annotator3_Scores!F6) -> 3 | H25: =AVERAGE(Annotator1_Scores!G6,Annotator2_Scores!G6,Annotator3_Scores!G6) -> 3 | I25: =SUM(F25:H25) -> 10 | J25: 20
A26: REQ-003 | B26: Authentication | C26: Password Reset via Email | D26: Medium | E26: Gemini | F26: =AVERAGE(Annotator1_Scores!I6,Annotator2_Scores!I6,Annotator3_Scores!I6) -> 3 | G26: =AVERAGE(Annotator1_Scores!J6,Annotator2_Scores!J6,Annotator3_Scores!J6) -> 3.3333333 | H26: =AVERAGE(Annotator1_Scores!K6,Annotator2_Scores!K6,Annotator3_Scores!K6) -> 3 | I26: =SUM(F26:H26) -> 9.3333333 | J26: 20
A27: REQ-003 | B27: Authentication | C27: Password Reset via Email | D27: Medium | E27: GPT-4o | F27: =AVERAGE(Annotator1_Scores!M6,Annotator2_Scores!M6,Annotator3_Scores!M6) -> 4.3333333 | G27: =AVERAGE(Annotator1_Scores!N6,Annotator2_Scores!N6,Annotator3_Scores!N6) -> 4 | H27: =AVERAGE(Annotator1_Scores!O6,Annotator2_Scores!O6,Annotator3_Scores!O6) -> 4 | I27: =SUM(F27:H27) -> 12.333333 | J27: 20
A28: REQ-003 | B28: Authentication | C28: Password Reset via Email | D28: Medium | E28: Claude | F28: =AVERAGE(Annotator1_Scores!Q6,Annotator2_Scores!Q6,Annotator3_Scores!Q6) -> 3.6666667 | G28: =AVERAGE(Annotator1_Scores!R6,Annotator2_Scores!R6,Annotator3_Scores!R6) -> 3.6666667 | H28: =AVERAGE(Annotator1_Scores!S6,Annotator2_Scores!S6,Annotator3_Scores!S6) -> 4 | I28: =SUM(F28:H28) -> 11.333333 | J28: 20
A29: REQ-003 | B29: Authentication | C29: Password Reset via Email | D29: Medium | E29: Llama 3.3 70B | F29: =AVERAGE(Annotator1_Scores!U6,Annotator2_Scores!U6,Annotator3_Scores!U6) -> 3.3333333 | G29: =AVERAGE(Annotator1_Scores!V6,Annotator2_Scores!V6,Annotator3_Scores!V6) -> 3.6666667 | H29: =AVERAGE(Annotator1_Scores!W6,Annotator2_Scores!W6,Annotator3_Scores!W6) -> 3 | I29: =SUM(F29:H29) -> 10 | J29: 20
A30: REQ-003 | B30: Authentication | C30: Password Reset via Email | D30: Medium | E30: Mistral Large 2 | F30: =AVERAGE(Annotator1_Scores!Y6,Annotator2_Scores!Y6,Annotator3_Scores!Y6) -> 3 | G30: =AVERAGE(Annotator1_Scores!Z6,Annotator2_Scores!Z6,Annotator3_Scores!Z6) -> 3.3333333 | H30: =AVERAGE(Annotator1_Scores!AA6,Annotator2_Scores!AA6,Annotator3_Scores!AA6) -> 3 | I30: =SUM(F30:H30) -> 9.3333333 | J30: 20
A31: REQ-003 | B31: Authentication | C31: Password Reset via Email | D31: Medium | E31: DeepSeek-V3 | F31: =AVERAGE(Annotator1_Scores!AC6,Annotator2_Scores!AC6,Annotator3_Scores!AC6) -> 3 | G31: =AVERAGE(Annotator1_Scores!AD6,Annotator2_Scores!AD6,Annotator3_Scores!AD6) -> 3.3333333 | H31: =AVERAGE(Annotator1_Scores!AE6,Annotator2_Scores!AE6,Annotator3_Scores!AE6) -> 3.6666667 | I31: =SUM(F31:H31) -> 10 | J31: 20
A32: REQ-003 | B32: Authentication | C32: Password Reset via Email | D32: Medium | E32: Grok-2 | F32: =AVERAGE(Annotator1_Scores!AG6,Annotator2_Scores!AG6,Annotator3_Scores!AG6) -> 3.6666667 | G32: =AVERAGE(Annotator1_Scores!AH6,Annotator2_Scores!AH6,Annotator3_Scores!AH6) -> 3.3333333 | H32: =AVERAGE(Annotator1_Scores!AI6,Annotator2_Scores!AI6,Annotator3_Scores!AI6) -> 3.6666667 | I32: =SUM(F32:H32) -> 10.666667 | J32: 20
A33: REQ-003 | B33: Authentication | C33: Password Reset via Email | D33: Medium | E33: Qwen2.5 72B | F33: =AVERAGE(Annotator1_Scores!AK6,Annotator2_Scores!AK6,Annotator3_Scores!AK6) -> 3.6666667 | G33: =AVERAGE(Annotator1_Scores!AL6,Annotator2_Scores!AL6,Annotator3_Scores!AL6) -> 3.6666667 | H33: =AVERAGE(Annotator1_Scores!AM6,Annotator2_Scores!AM6,Annotator3_Scores!AM6) -> 3.3333333 | I33: =SUM(F33:H33) -> 10.666667 | J33: 20
A34: REQ-003 | B34: Authentication | C34: Password Reset via Email | D34: Medium | E34: Command R+ | F34: =AVERAGE(Annotator1_Scores!AO6,Annotator2_Scores!AO6,Annotator3_Scores!AO6) -> 3 | G34: =AVERAGE(Annotator1_Scores!AP6,Annotator2_Scores!AP6,Annotator3_Scores!AP6) -> 3 | H34: =AVERAGE(Annotator1_Scores!AQ6,Annotator2_Scores!AQ6,Annotator3_Scores!AQ6) -> 3 | I34: =SUM(F34:H34) -> 9 | J34: 20
A35: REQ-003 | B35: Authentication | C35: Password Reset via Email | D35: Medium | E35: Gemma 2 27B | F35: =AVERAGE(Annotator1_Scores!AS6,Annotator2_Scores!AS6,Annotator3_Scores!AS6) -> 3.3333333 | G35: =AVERAGE(Annotator1_Scores!AT6,Annotator2_Scores!AT6,Annotator3_Scores!AT6) -> 3.6666667 | H35: =AVERAGE(Annotator1_Scores!AU6,Annotator2_Scores!AU6,Annotator3_Scores!AU6) -> 3.3333333 | I35: =SUM(F35:H35) -> 10.333333 | J35: 20
A36: REQ-004 | B36: Authentication | C36: Password Reset via OTP | D36: Medium | E36: ChatGPT | F36: =AVERAGE(Annotator1_Scores!E7,Annotator2_Scores!E7,Annotator3_Scores!E7) -> 3 | G36: =AVERAGE(Annotator1_Scores!F7,Annotator2_Scores!F7,Annotator3_Scores!F7) -> 3.3333333 | H36: =AVERAGE(Annotator1_Scores!G7,Annotator2_Scores!G7,Annotator3_Scores!G7) -> 3 | I36: =SUM(F36:H36) -> 9.3333333 | J36: 20
A37: REQ-004 | B37: Authentication | C37: Password Reset via OTP | D37: Medium | E37: Gemini | F37: =AVERAGE(Annotator1_Scores!I7,Annotator2_Scores!I7,Annotator3_Scores!I7) -> 4 | G37: =AVERAGE(Annotator1_Scores!J7,Annotator2_Scores!J7,Annotator3_Scores!J7) -> 3.3333333 | H37: =AVERAGE(Annotator1_Scores!K7,Annotator2_Scores!K7,Annotator3_Scores!K7) -> 3.3333333 | I37: =SUM(F37:H37) -> 10.666667 | J37: 20
A38: REQ-004 | B38: Authentication | C38: Password Reset via OTP | D38: Medium | E38: GPT-4o | F38: =AVERAGE(Annotator1_Scores!M7,Annotator2_Scores!M7,Annotator3_Scores!M7) -> 4 | G38: =AVERAGE(Annotator1_Scores!N7,Annotator2_Scores!N7,Annotator3_Scores!N7) -> 3.3333333 | H38: =AVERAGE(Annotator1_Scores!O7,Annotator2_Scores!O7,Annotator3_Scores!O7) -> 3.3333333 | I38: =SUM(F38:H38) -> 10.666667 | J38: 20
A39: REQ-004 | B39: Authentication | C39: Password Reset via OTP | D39: Medium | E39: Claude | F39: =AVERAGE(Annotator1_Scores!Q7,Annotator2_Scores!Q7,Annotator3_Scores!Q7) -> 3 | G39: =AVERAGE(Annotator1_Scores!R7,Annotator2_Scores!R7,Annotator3_Scores!R7) -> 3.6666667 | H39: =AVERAGE(Annotator1_Scores!S7,Annotator2_Scores!S7,Annotator3_Scores!S7) -> 3.3333333 | I39: =SUM(F39:H39) -> 10 | J39: 20
A40: REQ-004 | B40: Authentication | C40: Password Reset via OTP | D40: Medium | E40: Llama 3.3 70B | F40: =AVERAGE(Annotator1_Scores!U7,Annotator2_Scores!U7,Annotator3_Scores!U7) -> 3.3333333 | G40: =AVERAGE(Annotator1_Scores!V7,Annotator2_Scores!V7,Annotator3_Scores!V7) -> 3.3333333 | H40: =AVERAGE(Annotator1_Scores!W7,Annotator2_Scores!W7,Annotator3_Scores!W7) -> 3.3333333 | I40: =SUM(F40:H40) -> 10 | J40: 20
...

Sheet Error_Counts
A1: SCOTC v3.0 — Error Counts per Requirement × Model | 180 × 11 = 1,980 rows (fill after manual annotation)
A2: REQ_ID | B2: Domain | C2: Requirement | D2: Model | E2: ET-01 Missing Test Cases | F2: ET-02 Incorrect Test Steps | G2: ET-03 Vague Expected Results | H2: ET-04 Wrong Preconditions | I2: ET-05 Duplicate Test Cases | J2: ET-06 Missing Boundary Cases | K2: ET-07 Missing Negative Cases | L2: ET-08 Ambiguous Steps | M2: ET-09 Missing Preconditions | N2: ET-10 Missing Postconditions | O2: ET-11 Incomplete Test Data | P2: ET-12 Incorrect Expected Results | Q2: ET-13 Security Scenario Missing | R2: ET-14 Performance Scenario Missing | S2: ET-15 Usability Scenario Missing | T2: ET-16 Traceability Gap | U2: ET-17 Requirement Misinterpretation | V2: ET-18 Redundant Test Cases | W2: ET-19 Incorrect Priority Assignment | X2: ET-20 Duplicate Scenarios | Y2: Total Errors
A3: REQ-001 | B3: Authentication | C3: User Registration | D3: ChatGPT | E3: 2 | F3: 2 | G3: 2 | H3: 1 | I3: 0 | J3: 1 | K3: 3 | L3: 2 | M3: 2 | N3: 0 | O3: 2 | P3: 0 | Q3: 2 | R3: 1 | S3: 1 | T3: 1 | U3: 2 | V3: 0 | W3: 0 | X3: 0 | Y3: =SUM(E3:X3) -> 24
A4: REQ-001 | B4: Authentication | C4: User Registration | D4: Gemini | E4: 1 | F4: 1 | G4: 0 | H4: 1 | I4: 1 | J4: 0 | K4: 0 | L4: 3 | M4: 0 | N4: 1 | O4: 0 | P4: 0 | Q4: 3 | R4: 1 | S4: 2 | T4: 1 | U4: 3 | V4: 0 | W4: 0 | X4: 2 | Y4: =SUM(E4:X4) -> 20
A5: REQ-001 | B5: Authentication | C5: User Registration | D5: GPT-4o | E5: 0 | F5: 0 | G5: 2 | H5: 2 | I5: 1 | J5: 0 | K5: 1 | L5: 0 | M5: 1 | N5: 1 | O5: 0 | P5: 0 | Q5: 1 | R5: 1 | S5: 0 | T5: 0 | U5: 1 | V5: 0 | W5: 0 | X5: 0 | Y5: =SUM(E5:X5) -> 11
A6: REQ-001 | B6: Authentication | C6: User Registration | D6: Claude | E6: 1 | F6: 0 | G6: 1 | H6: 0 | I6: 0 | J6: 2 | K6: 1 | L6: 1 | M6: 1 | N6: 0 | O6: 1 | P6: 0 | Q6: 2 | R6: 0 | S6: 1 | T6: 0 | U6: 1 | V6: 0 | W6: 0 | X6: 1 | Y6: =SUM(E6:X6) -> 13
A7: REQ-001 | B7: Authentication | C7: User Registration | D7: Llama 3.3 70B | E7: 0 | F7: 1 | G7: 0 | H7: 1 | I7: 0 | J7: 0 | K7: 1 | L7: 2 | M7: 0 | N7: 0 | O7: 0 | P7: 1 | Q7: 2 | R7: 1 | S7: 2 | T7: 0 | U7: 0 | V7: 0 | W7: 0 | X7: 0 | Y7: =SUM(E7:X7) -> 11
A8: REQ-001 | B8: Authentication | C8: User Registration | D8: Mistral Large 2 | E8: 0 | F8: 0 | G8: 3 | H8: 0 | I8: 1 | J8: 0 | K8: 1 | L8: 0 | M8: 0 | N8: 0 | O8: 1 | P8: 0 | Q8: 3 | R8: 2 | S8: 0 | T8: 0 | U8: 0 | V8: 0 | W8: 0 | X8: 1 | Y8: =SUM(E8:X8) -> 12
A9: REQ-001 | B9: Authentication | C9: User Registration | D9: DeepSeek-V3 | E9: 0 | F9: 1 | G9: 2 | H9: 0 | I9: 0 | J9: 1 | K9: 1 | L9: 0 | M9: 0 | N9: 1 | O9: 2 | P9: 2 | Q9: 0 | R9: 2 | S9: 1 | T9: 0 | U9: 1 | V9: 0 | W9: 0 | X9: 0 | Y9: =SUM(E9:X9) -> 14
A10: REQ-001 | B10: Authentication | C10: User Registration | D10: Grok-2 | E10: 0 | F10: 0 | G10: 0 | H10: 0 | I10: 1 | J10: 1 | K10: 0 | L10: 1 | M10: 0 | N10: 1 | O10: 0 | P10: 0 | Q10: 1 | R10: 2 | S10: 1 | T10: 3 | U10: 0 | V10: 2 | W10: 0 | X10: 1 | Y10: =SUM(E10:X10) -> 14
A11: REQ-001 | B11: Authentication | C11: User Registration | D11: Qwen2.5 72B | E11: 2 | F11: 1 | G11: 3 | H11: 1 | I11: 1 | J11: 1 | K11: 0 | L11: 0 | M11: 0 | N11: 2 | O11: 0 | P11: 0 | Q11: 0 | R11: 1 | S11: 1 | T11: 0 | U11: 1 | V11: 0 | W11: 0 | X11: 0 | Y11: =SUM(E11:X11) -> 14
A12: REQ-001 | B12: Authentication | C12: User Registration | D12: Command R+ | E12: 0 | F12: 1 | G12: 3 | H12: 2 | I12: 3 | J12: 2 | K12: 0 | L12: 2 | M12: 2 | N12: 2 | O12: 2 | P12: 0 | Q12: 2 | R12: 3 | S12: 0 | T12: 0 | U12: 0 | V12: 0 | W12: 0 | X12: 2 | Y12: =SUM(E12:X12) -> 26
A13: REQ-001 | B13: Authentication | C13: User Registration | D13: Gemma 2 27B | E13: 1 | F13: 3 | G13: 2 | H13: 1 | I13: 0 | J13: 0 | K13: 1 | L13: 1 | M13: 3 | N13: 2 | O13: 2 | P13: 1 | Q13: 1 | R13: 1 | S13: 2 | T13: 0 | U13: 3 | V13: 0 | W13: 1 | X13: 0 | Y13: =SUM(E13:X13) -> 25
A14: REQ-002 | B14: Authentication | C14: User Login | D14: ChatGPT | E14: 1 | F14: 1 | G14: 2 | H14: 0 | I14: 0 | J14: 1 | K14: 0 | L14: 0 | M14: 1 | N14: 0 | O14: 2 | P14: 1 | Q14: 0 | R14: 2 | S14: 1 | T14: 0 | U14: 0 | V14: 0 | W14: 0 | X14: 0 | Y14: =SUM(E14:X14) -> 12
... A1982: REQ-180 | B1982: e-Governance | C1982: Document Apostille Request | D1982: Gemma 2 27B | E1982: 1 | F1982: 2 | G1982: 1 | H1982: 0 | I1982: 1 | J1982: 1 | K1982: 1 | L1982: 1 | M1982: 1 | N1982: 1 | O1982: 2 | P1982: 0 | Q1982: 1 | R1982: 1 | S1982: 2 | T1982: 1 | U1982: 0 | V1982: 2 | W1982: 1 | X1982: 0 | Y1982: =SUM(E1982:X1982) -> 20

Sheet Error_Taxonomy
A1: SCOTC v3.0 — Error Taxonomy (20 Types × 7 Categories)
A2: Classify defects found in LLM-generated test scenarios. A single scenario may carry multiple error types. Severity guides prioritisation.
A4: Error_ID | B4: Category | C4: Error_Type | D4: Description | E4: Example | F4: Severity
A5: ET-01 | B5: Original | C5: Missing Test Cases | D5: Required functional paths not covered by any scenario | E5: Login with expired token not tested | F5: High
A6: ET-02 | B6: Original | C6: Incorrect Test Steps | D6: Steps do not logically lead to the expected result | E6: Step says Click Submit before form is filled | F6: High
A7: ET-03 | B7: Original | C7: Vague Expected Results | D7: Expected result too generic to verify pass/fail | E7: System should work correctly | F7: Medium
A8: ET-04 | B8: Original | C8: Wrong Preconditions | D8: Preconditions irrelevant or incorrect for the scenario | E8: User is logged out stated for a post-login test | F8: Medium
A9: ET-05 | B9: Original | C9: Duplicate Test Cases | D9: Two or more scenarios test identical functionality | E9: TS-01 and TS-03 both test valid login | F9: Low
A10: ET-06 | B10: Boundary | C10: Missing Boundary Cases | D10: Edge values (min/max/zero/null) not tested | E10: Password max-length boundary not tested | F10: High
A11: ET-07 | B11: Boundary | C11: Missing Negative Cases | D11: Invalid inputs or failure paths not included | E11: No test for submitting empty required fields | F11: High
A12: ET-08 | B12: Structural | C12: Ambiguous Steps | D12: Steps unclear or open to multiple interpretations | E12: Navigate to the relevant page — which page? | F12: Medium
A13: ET-09 | B13: Structural | C13: Missing Preconditions | D13: Scenario assumes state that is never established | E13: No precondition that test account exists | F13: High
A14: ET-10 | B14: Structural | C14: Missing Postconditions | D14: No verification of system state after test completion | E14: Does not confirm DB record was created | F14: Medium
A15: ET-11 | B15: Data | C15: Incomplete Test Data | D15: Test data values not specified or unrealistic | E15: Uses placeholder test@test.com without variation | F15: Medium
... A24: ET-20 | B24: Structural | C24: Duplicate Scenarios | D24: Identical scenario appears more than once with diff IDs | E24: TS-04 and TS-09 are word-for-word duplicates | F24: Low

Sheet LLM_Outputs
A1: REQ_ID | B1: Domain | C1: Requirement | D1: Complexity | E1: Model | F1: LLM_Output_Paste_Here
A2: REQ-001 | B2: Authentication | C2: User Registration | D2: Medium | E2: ChatGPT | F2: [PASTE CHATGPT RESPONSE FOR REQ-001 HERE] Prompt used: You are a software test engineer. Given the following functional requirement from a Software Requirements Specification (SRS), generate test scenarios that fully cover this requirement. Requirement: User Registration For each test scenario, provide: 1. Test Scenario ID 2. Scenario Description 3. Preconditions 4. Test Steps 5. Expected Result Generate as many scenarios as needed for complete coverage.
A3: REQ-001 | B3: Authentication | C3: User Registration | D3: Medium | E3: Gemini | F3: [PASTE GEMINI RESPONSE FOR REQ-001 HERE] Prompt used: You are a software test engineer. Given the following functional requirement from a Software Requirements Specification (SRS), generate test scenarios that fully cover this requirement. Requirement: User Registration For each test scenario, provide: 1. Test Scenario ID 2. Scenario Description 3. Preconditions 4. Test Steps 5. Expected Result Generate as many scenarios as needed for complete coverage.
A4: REQ-001 | B4: Authentication | C4: User Registration | D4: Medium | E4: GPT-4o | F4: [PASTE GPT-4O RESPONSE FOR REQ-001 HERE] Prompt used: You are a software test engineer. Given the following functional requirement from a Software Requirements Specification (SRS), generate test scenarios that fully cover this requirement. Requirement: User Registration For each test scenario, provide: 1. Test Scenario ID 2. Scenario Description 3. Preconditions 4. Test Steps 5. Expected Result Generate as many scenarios as needed for complete coverage.
A5: REQ-001 | B5: Authentication | C5: User Registration | D5: Medium | E5: Claude | F5: [PASTE CLAUDE RESPONSE FOR REQ-001 HERE] Prompt used: You are a software test engineer. Given the following functional requirement from a Software Requirements Specification (SRS), generate test scenarios that fully cover this requirement. Requirement: User Registration For each test scenario, provide: 1. Test Scenario ID 2. Scenario Description 3. Preconditions 4. Test Steps 5. Expected Result Generate as many scenarios as needed for complete coverage.
A6: REQ-001 | B6: Authentication | C6: User Registration | D6: Medium | E6: Llama 3.3 70B | F6: [PASTE LLAMA 3.3 70B RESPONSE FOR REQ-001 HERE] Prompt used: You are a software test engineer. Given the following functional requirement from a Software Requirements Specification (SRS), generate test scenarios that fully cover this requirement. Requirement: User Registration For each test scenario, provide: 1. Test Scenario ID 2. Scenario Description 3. Preconditions 4. Test Steps 5. Expected Result Generate as many scenarios as needed for complete coverage.
A7: REQ-001 | B7: Authentication | C7: User Registration | D7: Medium | E7: Mistral Large 2 | F7: [PASTE MISTRAL LARGE 2 RESPONSE FOR REQ-001 HERE] Prompt used: You are a software test engineer. Given the following functional requirement from a Software Requirements Specification (SRS), generate test scenarios that fully cover this requirement. Requirement: User Registration For each test scenario, provide: 1. Test Scenario ID 2. Scenario Description 3. Preconditions 4. Test Steps 5. Expected Result Generate as many scenarios as needed for complete coverage.
A8: REQ-001 | B8: Authentication | C8: User Registration | D8: Medium | E8: DeepSeek-V3 | F8: [PASTE DEEPSEEK-V3 RESPONSE FOR REQ-001 HERE] Prompt used: You are a software test engineer. Given the following functional requirement from a Software Requirements Specification (SRS), generate test scenarios that fully cover this requirement. Requirement: User Registration For each test scenario, provide: 1. Test Scenario ID 2. Scenario Description 3. Preconditions 4. Test Steps 5. Expected Result Generate as many scenarios as needed for complete coverage.
A9: REQ-001 | B9: Authentication | C9: User Registration | D9: Medium | E9: Grok-2 | F9: [PASTE GROK-2 RESPONSE FOR REQ-001 HERE] Prompt used: You are a software test engineer. Given the following functional requirement from a Software Requirements Specification (SRS), generate test scenarios that fully cover this requirement. Requirement: User Registration For each test scenario, provide: 1. Test Scenario ID 2. Scenario Description 3. Preconditions 4. Test Steps 5. Expected Result Generate as many scenarios as needed for complete coverage.
A10: REQ-001 | B10: Authentication | C10: User Registration | D10: Medium | E10: Qwen2.5 72B | F10: [PASTE QWEN2.5 72B RESPONSE FOR REQ-001 HERE] Prompt used: You are a software test engineer. Given the following functional requirement from a Software Requirements Specification (SRS), generate test scenarios that fully cover this requirement. Requirement: User Registration For each test scenario, provide: 1. Test Scenario ID 2. Scenario Description 3. Preconditions 4. Test Steps 5. Expected Result Generate as many scenarios as needed for complete coverage.
A11: REQ-001 | B11: Authentication | C11: User Registration | D11: Medium | E11: Command R+ | F11: [PASTE COMMAND R+ RESPONSE FOR REQ-001 HERE] Prompt used: You are a software test engineer. Given the following functional requirement from a Software Requirements Specification (SRS), generate test scenarios that fully cover this requirement. Requirement: User Registration For each test scenario, provide: 1. Test Scenario ID 2. Scenario Description 3. Preconditions 4. Test Steps 5. Expected Result Generate as many scenarios as needed for complete coverage.
